Workbook

Sheet sample_event_meta
A1: year | B1: gear | C1: gear_detailed | D1: date_start | E1: time_start | F1: date_stop | G1: time_stop | H1: vessel | I1: dock_departure_time | J1: weather | K1: wind | L1: crew | M1: set_type | N1: set_no | O1: site_name_raw | P1: site_name_CLEAN | Q1: lat_DD | R1: long_DD | S1: form1-ID | T1: form2-ID | U1: usid | V1: comments
A2: 2023 | B2: 6' RST | D2: 45008 | E2: 16:30 | F2: 45009 | G2: 09:00 | L2: KD, PV, PFN | M2: Night | O2: Rod's | Q2: 48.5778 | R2: -124.30415 | U2: =CONCATENATE(TEXT(F2,"ddmmmyy"),"-",IF(B2="CCFS purse seine","PRS", IF(B2="PFN pole seine","POS", IF(B2="6' RST","RST", IF(B2="PFN beach seine","BS", "FLAG")))), IF(ISBLANK(N2), CONCATENATE("-",M2), CONCATENATE("-",N2))) -> 24Mar23-RST-Night
A3: 2023 | B3: 6' RST | D3: 45014 | E3: 16:40 | F3: 45015 | G3: 09:00 | J3: overcast | L3: AJ, JJ, Chris McAulay, MDJ, KD, AJ | M3: Night | O3: Rod's | Q3: 48.5778 | R3: -124.30415 | U3: =CONCATENATE(TEXT(F3,"ddmmmyy"),"-",IF(B3="CCFS purse seine","PRS", IF(B3="PFN pole seine","POS", IF(B3="6' RST","RST", IF(B3="PFN beach seine","BS", "FLAG")))), IF(ISBLANK(N3), CONCATENATE("-",M3), CONCATENATE("-",N3))) -> 30Mar23-RST-Night
A4: 2023 | B4: 6' RST | D4: 45015 | E4: 18:40 | F4: 45016 | G4: 08:55 | J4: light rain, overcast | L4: AJx2, JJ, KD, CM, MDJ | M4: Night | O4: Rod's | Q4: 48.5778 | R4: -124.30415 | U4: =CONCATENATE(TEXT(F4,"ddmmmyy"),"-",IF(B4="CCFS purse seine","PRS", IF(B4="PFN pole seine","POS", IF(B4="6' RST","RST", IF(B4="PFN beach seine","BS", "FLAG")))), IF(ISBLANK(N4), CONCATENATE("-",M4), CONCATENATE("-",N4))) -> 31Mar23-RST-Night
A5: 2023 | B5: 6' RST | D5: 45020 | E5: 18:20 | F5: 45021 | G5: 09:00 | J5: high light cloud/sun, very light breeze | L5: CM, AJ, TL, AN, HJ | M5: Night | O5: Rod's | Q5: 48.5778 | R5: -124.30415 | U5: =CONCATENATE(TEXT(F5,"ddmmmyy"),"-",IF(B5="CCFS purse seine","PRS", IF(B5="PFN pole seine","POS", IF(B5="6' RST","RST", IF(B5="PFN beach seine","BS", "FLAG")))), IF(ISBLANK(N5), CONCATENATE("-",M5), CONCATENATE("-",N5))) -> 05Apr23-RST-Night
A6: 2023 | B6: 6' RST | D6: 45021 | E6: 18:15 | F6: 45022 | G6: 09:15 | J6: Rainy! | L6: JF, KD, AN, RJ, JJ, AJ | M6: Night | O6: Rod's | Q6: 48.5778 | R6: -124.30415 | U6: =CONCATENATE(TEXT(F6,"ddmmmyy"),"-",IF(B6="CCFS purse seine","PRS", IF(B6="PFN pole seine","POS", IF(B6="6' RST","RST", IF(B6="PFN beach seine","BS", "FLAG")))), IF(ISBLANK(N6), CONCATENATE("-",M6), CONCATENATE("-",N6))) -> 06Apr23-RST-Night
A7: 2023 | B7: 6' RST | D7: 45035 | E7: 18:00 | F7: 45036 | G7: 09:00 | J7: Overcast | L7: ML, MDJ, JJ, AJ, TL | M7: Night | O7: Rod's | Q7: 48.5778 | R7: -124.30415 | U7: =CONCATENATE(TEXT(F7,"ddmmmyy"),"-",IF(B7="CCFS purse seine","PRS", IF(B7="PFN pole seine","POS", IF(B7="6' RST","RST", IF(B7="PFN beach seine","BS", "FLAG")))), IF(ISBLANK(N7), CONCATENATE("-",M7), CONCATENATE("-",N7))) -> 20Apr23-RST-Night
A8: 2023 | B8: 6' RST | D8: 45028 | E8: 18:00 | F8: 45029 | G8: 09:00 | J8: overcast | L8: JR, AJ, RJ | M8: Night | O8: Rod's | Q8: 48.5778 | R8: -124.30415 | U8: =CONCATENATE(TEXT(F8,"ddmmmyy"),"-",IF(B8="CCFS purse seine","PRS", IF(B8="PFN pole seine","POS", IF(B8="6' RST","RST", IF(B8="PFN beach seine","BS", "FLAG")))), IF(ISBLANK(N8), CONCATENATE("-",M8), CONCATENATE("-",N8))) -> 13Apr23-RST-Night
A9: 2023 | B9: 6' RST | D9: 45036 | E9: 19:30 | F9: 45037 | G9: 09:00 | J9: overcast | L9: JR, AJ, TL,ML | M9: Night | O9: Rod's | Q9: 48.5778 | R9: -124.30415 | U9: =CONCATENATE(TEXT(F9,"ddmmmyy"),"-",IF(B9="CCFS purse seine","PRS", IF(B9="PFN pole seine","POS", IF(B9="6' RST","RST", IF(B9="PFN beach seine","BS", "FLAG")))), IF(ISBLANK(N9), CONCATENATE("-",M9), CONCATENATE("-",N9))) -> 21Apr23-RST-Night
A10: 2023 | B10: dip net | D10: 45040 | F10: 45040 | L10: Lisa Margetish/Shane Bruinsma | O10: Hatchery tanks (tank #4) | U10: 14Apr23-HATTK-4 | V10: custom USID to link hatchery samples to sampling event (# is tank #)
A11: 2023 | B11: 6' RST | D11: 45042 | E11: 17:45 | F11: 45043 | G11: 09:05 | J11: sunny, light breeze | L11: JRAJ, AJ, RJ, TL | M11: Night | O11: Rod's | Q11: 48.5778 | R11: -124.30415 | U11: =CONCATENATE(TEXT(F11,"ddmmmyy"),"-",IF(B11="CCFS purse seine","PRS", IF(B11="PFN pole seine","POS", IF(B11="6' RST","RST", IF(B11="PFN beach seine","BS", "FLAG")))), IF(ISBLANK(N11), CONCATENATE("-",M11), CONCATENATE("-",N11))) -> 27Apr23-RST-Night
A12: 2023 | B12: 6' RST | D12: 45043 | E12: 10:55 | F12: 45043 | G12: 17:00 | J12: sunny, light breeze | L12: JRAJ, AJ RJ, TL | M12: Day | O12: Rod's | Q12: 48.5778 | R12: -124.30415 | U12: =CONCATENATE(TEXT(F12,"ddmmmyy"),"-",IF(B12="CCFS purse seine","PRS", IF(B12="PFN pole seine","POS", IF(B12="6' RST","RST", IF(B12="PFN beach seine","BS", "FLAG")))), IF(ISBLANK(N12), CONCATENATE("-",M12), CONCATENATE("-",N12))) -> 27Apr23-RST-Day
A13: 2023 | B13: 6' RST | D13: 45043 | E13: 18:00 | F13: 45044 | G13: 08:35 | J13: sunny, no wind | L13: JRAJ, AJ RJ, TL | M13: Night | O13: Rod's | Q13: 48.5778 | R13: -124.30415 | U13: =CONCATENATE(TEXT(F13,"ddmmmyy"),"-",IF(B13="CCFS purse seine","PRS", IF(B13="PFN pole seine","POS", IF(B13="6' RST","RST", IF(B13="PFN beach seine","BS", "FLAG")))), IF(ISBLANK(N13), CONCATENATE("-",M13), CONCATENATE("-",N13))) -> 28Apr23-RST-Night
A14: 2023 | B14: 6' RST | D14: 45050 | E14: 16:30 | F14: 45051 | G14: 09:00 | J14: Raining | L14: RJ, JJ, AJ, TL | M14: Night | O14: Rod's | Q14: 48.5778 | R14: -124.30415 | U14: =CONCATENATE(TEXT(F14,"ddmmmyy"),"-",IF(B14="CCFS purse seine","PRS", IF(B14="PFN pole seine","POS", IF(B14="6' RST","RST", IF(B14="PFN beach seine","BS", "FLAG")))), IF(ISBLANK(N14), CONCATENATE("-",M14), CONCATENATE("-",N14))) -> 05May23-RST-Night
A15: 2023 | B15: PFN pole seine | D15: 45051 | E15: 10:15 | F15: 45051 | G15: 10:12 | J15: light rain | L15: JRAJ, RJ, AJ, TL, KD | N15: 1 | O15: Rod's drainage ditch | Q15: 48.577906 | R15: -124.3041 | U15: =CONCATENATE(TEXT(F15,"ddmmmyy"),"-",IF(B15="CCFS purse seine","PRS", IF(B15="PFN pole seine","POS", IF(B15="6' RST","RST", IF(B15="PFN beach seine","BS", "FLAG")))), IF(ISBLANK(N15), CONCATENATE("-",M15), CONCATENATE("-",N15))) -> 05May23-POS-1 | V15: lat/long are estimates from Google Earth
A16: 2023 | B16: 6' RST | D16: 45056 | E16: 16:10 | F16: 45057 | G16: 09:05 | J16: sunny, clear | L16: JRAJ, MDJ, TL, AJ | M16: Night | O16: Rod's | Q16: 48.5778 | R16: -124.30415 | U16: =CONCATENATE(TEXT(F16,"ddmmmyy"),"-",IF(B16="CCFS purse seine","PRS", IF(B16="PFN pole seine","POS", IF(B16="6' RST","RST", IF(B16="PFN beach seine","BS", "FLAG")))), IF(ISBLANK(N16), CONCATENATE("-",M16), CONCATENATE("-",N16))) -> 11May23-RST-Night
A17: 2023 | B17: dip net | D17: 45072 | F17: 45072 | L17: Lisa Margetish/Shane Bruinsma | O17: Hatchery sea pen | Q17: 48.547679 | R17: -124.43926 | U17: 26May23-HATSP-1 | V17: custom USID to link hatchery samples to sampling event
A18: 2023 | B18: 6' RST | D18: 45078 | E18: 16:45 | F18: 45079 | G18: 09:10 | J18: sunny, clear | L18: JRAJ | M18: Night | O18: Rod's | Q18: 48.5778 | R18: -124.30415 | U18: =CONCATENATE(TEXT(F18,"ddmmmyy"),"-",IF(B18="CCFS purse seine","PRS", IF(B18="PFN pole seine","POS", IF(B18="6' RST","RST", IF(B18="PFN beach seine","BS", "FLAG")))), IF(ISBLANK(N18), CONCATENATE("-",M18), CONCATENATE("-",N18))) -> 02Jun23-RST-Night
A19: 2023 | B19: dip net | D19: 45079 | O19: Hatchery lake pens in Fairy Lake/SJ confl | Q19: 48.581622 | R19: -124.34157 | U19: 02Jun23-HATLP-1 | V19: custom USID to link hatchery samples to sampling event
A20: 2023 | B20: 6' RST | D20: 45084 | E20: 16:10 | F20: 45085 | G20: 09:15 | J20: sunny, windy | L20: JRAJ, MDJ, AJ, TL, CM | M20: Night | O20: Rod's | Q20: 48.5778 | R20: -124.30415 | U20: =CONCATENATE(TEXT(F20,"ddmmmyy"),"-",IF(B20="CCFS purse seine","PRS", IF(B20="PFN pole seine","POS", IF(B20="6' RST","RST", IF(B20="PFN beach seine","BS", "FLAG")))), IF(ISBLANK(N20), CONCATENATE("-",M20), CONCATENATE("-",N20))) -> 08Jun23-RST-Night
A21: 2023 | B21: 6' RST | D21: 45085 | E21: 15:35 | F21: 45086 | G21: 09:00 | J21: light rain | L21: JRAJ, MDJ, TL, CM | M21: Night | O21: Rod's | Q21: 48.5778 | R21: -124.30415 | U21: =CONCATENATE(TEXT(F21,"ddmmmyy"),"-",IF(B21="CCFS purse seine","PRS", IF(B21="PFN pole seine","POS", IF(B21="6' RST","RST", IF(B21="PFN beach seine","BS", "FLAG")))), IF(ISBLANK(N21), CONCATENATE("-",M21), CONCATENATE("-",N21))) -> 09Jun23-RST-Night
A22: 2023 | B22: dip net | D22: 45089 | F22: 45089 | L22: LM, SB | O22: Hatchery sea pen | Q22: 48.547679 | R22: -124.43926 | U22: 12Jun23-HATSP-1 | V22: custom USID to link hatchery samples to sampling event
A23: 2023 | B23: 6' RST | D23: 45091 | E23: 16:30 | F23: 45092 | G23: 08:45 | L23: JRAJ, MDJ, TL, CM | M23: Night | O23: Rod's | Q23: 48.5778 | R23: -124.30415 | U23: =CONCATENATE(TEXT(F23,"ddmmmyy"),"-",IF(B23="CCFS purse seine","PRS", IF(B23="PFN pole seine","POS", IF(B23="6' RST","RST", IF(B23="PFN beach seine","BS", "FLAG")))), IF(ISBLANK(N23), CONCATENATE("-",M23), CONCATENATE("-",N23))) -> 15Jun23-RST-Night
A24: 2023 | B24: 6' RST | D24: 45092 | E24: 15:37 | F24: 45093 | G24: 08:52 | J24: heavy fog | L24: JRAJ, AJ, TL, Mya | M24: Night | O24: Rod's | Q24: 48.5778 | R24: -124.30415 | U24: =CONCATENATE(TEXT(F24,"ddmmmyy"),"-",IF(B24="CCFS purse seine","PRS", IF(B24="PFN pole seine","POS", IF(B24="6' RST","RST", IF(B24="PFN beach seine","BS", "FLAG")))), IF(ISBLANK(N24), CONCATENATE("-",M24), CONCATENATE("-",N24))) -> 16Jun23-RST-Night
A25: 2023 | B25: PFN beach seine | D25: 45092 | F25: 45092 | H25: PFN BS boat | I25: 11:00 | L25: CM, JRAJ, AJ, TL | N25: 1 | O25: FLBS01 - San Juan @ Fairy Lake confl | P25: FLBS01 | Q25: 48.58176 | R25: -124.34077 | U25: =CONCATENATE(TEXT(F25,"ddmmmyy"),"-",IF(B25="CCFS purse seine","PRS", IF(B25="PFN pole seine","POS", IF(B25="6' RST","RST", IF(B25="PFN beach seine","BS", "FLAG")))), IF(ISBLANK(N25), CONCATENATE("-",M25), CONCATENATE("-",N25))) -> 15Jun23-BS-1 | V25: Set 1 was for enumeration with Pacheedaht - data stored in PFN database
A26: 2023 | B26: PFN beach seine | D26: 45092 | F26: 45092 | H26: PFN BS boat | I26: 11:00 | L26: CM, JRAJ, AJ, TL | N26: 2 | O26: FLBS01 - San Juan @ Fairy Lake confl | P26: FLBS01 | Q26: 48.58176 | R26: -124.34077 | U26: =CONCATENATE(TEXT(F26,"ddmmmyy"),"-",IF(B26="CCFS purse seine","PRS", IF(B26="PFN pole seine","POS", IF(B26="6' RST","RST", IF(B26="PFN beach seine","BS", "FLAG")))), IF(ISBLANK(N26), CONCATENATE("-",M26), CONCATENATE("-",N26))) -> 15Jun23-BS-2 | V26: Sets 2 and 3 for chinook samples so not fully enumerated apart from 15 coho fry and 2 coho smolts in set #2
A27: 2023 | B27: PFN beach seine | D27: 45092 | F27: 45092 | H27: PFN BS boat | I27: 11:00 | L27: CM, JRAJ, AJ, TL | N27: 3 | O27: FLBS01 - San Juan @ Fairy Lake confl | P27: FLBS01 | Q27: 48.58176 | R27: -124.34077 | U27: =CONCATENATE(TEXT(F27,"ddmmmyy"),"-",IF(B27="CCFS purse seine","PRS", IF(B27="PFN pole seine","POS", IF(B27="6' RST","RST", IF(B27="PFN beach seine","BS", "FLAG")))), IF(ISBLANK(N27), CONCATENATE("-",M27), CONCATENATE("-",N27))) -> 15Jun23-BS-3
A28: 2023 | B28: PFN beach seine | D28: 45093 | E28: 11:30 | F28: 45093 | G28: 11:35 | H28: PFN BS boat | I28: 11:00 | J28: rainy | L28: JRAJ, AJ, TL, KD | N28: 1 | O28: BS24 - WCT head Gordon River | P28: BS24 | Q28: 48.576744 | R28: -124.41629 | U28: =CONCATENATE(TEXT(F28,"ddmmmyy"),"-",IF(B28="CCFS purse seine","PRS", IF(B28="PFN pole seine","POS", IF(B28="6' RST","RST", IF(B28="PFN beach seine","BS", "FLAG")))), IF(ISBLANK(N28), CONCATENATE("-",M28), CONCATENATE("-",N28))) -> 16Jun23-BS-1
A29: 2023 | B29: PFN beach seine | D29: 45093 | E29: 12:50 | F29: 45093 | G29: 12:54 | H29: PFN BS boat | I29: 11:00 | J29: rainy | L29: JRAJ, AJ, TL, KD | N29: 2 | O29: BS07 - near boat launch Gordon River. Butch's in PFN database. | P29: BS07 | Q29: 48.578887 | R29: -124.41334 | U29: =CONCATENATE(TEXT(F29,"ddmmmyy"),"-",IF(B29="CCFS purse seine","PRS", IF(B29="PFN pole seine","POS", IF(B29="6' RST","RST", IF(B29="PFN beach seine","BS", "FLAG")))), IF(ISBLANK(N29), CONCATENATE("-",M29), CONCATENATE("-",N29))) -> 16Jun23-BS-2 | V29: no salmon caught
A30: 2023 | B30: PFN beach seine | D30: 45093 | E30: 13:05 | F30: 45093 | G30: 13:10 | H30: PFN BS boat | I30: 11:00 | J30: rainy | L30: JRAJ, AJ, TL, KD | N30: 3 | O30: BS24 - WCT head Gordon River | P30: BS24 | Q30: 48.576744 | R30: -124.41629 | U30: =CONCATENATE(TEXT(F30,"ddmmmyy"),"-",IF(B30="CCFS purse seine","PRS", IF(B30="PFN pole seine","POS", IF(B30="6' RST","RST", IF(B30="PFN beach seine","BS", "FLAG")))), IF(ISBLANK(N30), CONCATENATE("-",M30), CONCATENATE("-",N30))) -> 16Jun23-BS-3
A31: 2023 | B31: Mini purse seine | C31: CCFS mini purse seine net | D31: 45105 | E31: 09:32 | F31: 45105 | G31: 09:45 | H31: Warriors Three | I31: 09:30 | J31: sunny, windy, very warm | L31: KD, JJ, MDJ, TL, JRAJ, AJ | N31: 1 | O31: Breakwater at PGM | P31: PGM | Q31: 48.55775 | R31: -124.41442 | U31: =CONCATENATE(TEXT(F31,"ddmmmyy"),"-",IF(B31="Mini purse seine","PRS", IF(B31="PFN pole seine","POS", IF(B31="6' RST","RST", IF(B31="PFN beach seine","BS", IF(B31="IPT", "IPT", "FLAG"))))), IF(ISBLANK(N31), CONCATENATE("-",M31), CONCATENATE("-",P31,"-",N31))) -> 28Jun23-PRS-PGM-1 | V31: first set, bit tangled but good. Waypoint on Katie's phone Navionics.
A32: 2023 | B32: Mini purse seine | C32: CCFS mini purse seine net | D32: 45105 | E32: 10:28 | F32: 45105 | G32: 10:35 | H32: Warriors Three | I32: 09:30 | J32: sunny, windy, very warm | L32: KD, JJ, MDJ, TL, JRAJ, AJ | N32: 2 | O32: Govt/community wharf PRCD | P32: PRCD | Q32: 48.55597 | R32: -124.42198 | U32: =CONCATENATE(TEXT(F32,"ddmmmyy"),"-",IF(B32="Mini purse seine","PRS", IF(B32="PFN pole seine","POS", IF(B32="6' RST","RST", IF(B32="PFN beach seine","BS", IF(B32="IPT", "IPT", "FLAG"))))), IF(ISBLANK(N32), CONCATENATE("-",M32), CONCATENATE("-",P32,"-",N32))) -> 28Jun23-PRS-PRCD-2 | V32: coarse mesh snagged on boat during set. Waypoint on Katie's phone Gaia.
A33: 2023 | B33: Mini purse seine | C33: CCFS mini purse seine net | D33: 45105 | E33: 11:35 | F33: 45105 | G33: 11:41 | H33: Warriors Three | I33: 09:30 | J33: sunny, windy, very warm | L33: KD, JJ, MDJ, TL, JRAJ, AJ | N33: 3 | O33: Mill Bay/BBR | P33: Mill Bay | Q33: 48.549444 | R33: -124.43972 | U33: =CONCATENATE(TEXT(F33,"ddmmmyy"),"-",IF(B33="Mini purse seine","PRS", IF(B33="PFN pole seine","POS", IF(B33="6' RST","RST", IF(B33="PFN beach seine","BS", IF(B33="IPT", "IPT", "FLAG"))))), IF(ISBLANK(N33), CONCATENATE("-",M33), CONCATENATE("-",P33,"-",N33))) -> 28Jun23-PRS-Mill Bay-3 | V33: net tangled when deployed. Started doing waypoints on PFN tablet Avenza. Nothing caught.
A34: 2023 | B34: Mini purse seine | C34: CCFS mini purse seine net | D34: 45105 | E34: 12:02 | F34: 45105 | G34: 12:15 | H34: Warriors Three | I34: 09:30 | J34: sunny, windy, very warm | L34: KD, JJ, MDJ, TL, JRAJ, AJ | N34: 4 | O34: Thrasher Cove | P34: Thrasher | Q34: 48.55644 | R34: -124.46642 | U34: =CONCATENATE(TEXT(F34,"ddmmmyy"),"-",IF(B34="Mini purse seine","PRS", IF(B34="PFN pole seine","POS", IF(B34="6' RST","RST", IF(B34="PFN beach seine","BS", IF(B34="IPT", "IPT", "FLAG"))))), IF(ISBLANK(N34), CONCATENATE("-",M34), CONCATENATE("-",P34,"-",N34))) -> 28Jun23-PRS-Thrasher-4 | V34: tangled set
A35: 2023 | B35: Mini purse seine | C35: CCFS mini purse seine net | D35: 45105 | E35: 13:36 | F35: 45105 | G35: 13:43 | H35: Warriors Three | I35: 09:30 | J35: sunny, windy, very warm | L35: KD, JJ, MDJ, TL, JRAJ, AJ | N35: 5 | O35: Jap rock | P35: Jap Rock | Q35: 48.564722 | R35: -124.44083 | U35: =CONCATENATE(TEXT(F35,"ddmmmyy"),"-",IF(B35="Mini purse seine","PRS", IF(B35="PFN pole seine","POS", IF(B35="6' RST","RST", IF(B35="PFN beach seine","BS", IF(B35="IPT", "IPT", "FLAG"))))), IF(ISBLANK(N35), CONCATENATE("-",M35), CONCATENATE("-",P35,"-",N35))) -> 28Jun23-PRS-Jap Rock-5
A36: 2023 | B36: Mini purse seine | C36: CCFS mini purse seine net | D36: 45114 | E36: 09:22 | F36: 45114 | G36: 09:29 | H36: Warriors Three | I36: 09:15 | J36: overcast, choppy | L36: CM, pfn crew? | N36: 1 | P36: Gordon R | Q36: 48.567361 | R36: -124.42908 | U36: =CONCATENATE(TEXT(F36,"ddmmmyy"),"-",IF(B36="Mini purse seine","PRS", IF(B36="PFN pole seine","POS", IF(B36="6' RST","RST", IF(B36="PFN beach seine","BS", IF(B36="IPT", "IPT", "FLAG"))))), IF(ISBLANK(N36), CONCATENATE("-",M36), CONCATENATE("-",P36,"-",N36))) -> 07Jul23-PRS-Gordon R-1 | V36: net was backwards, no fish. No coeanography.
A37: 2023 | B37: Mini purse seine | C37: CCFS mini purse seine net | D37: 45114 | E37: 09:35 | F37: 45114 | G37: 09:44 | H37: Warriors Three | I37: 09:15 | J37: overcast, choppy | L37: CM, pfn crew? | N37: 2 | P37: Gordon R | Q37: 48.566753 | R37: -124.43136 | U37: =CONCATENATE(TEXT(F37,"ddmmmyy"),"-",IF(B37="Mini purse seine","PRS", IF(B37="PFN pole seine","POS", IF(B37="6' RST","RST", IF(B37="PFN beach seine","BS", IF(B37="IPT", "IPT", "FLAG"))))), IF(ISBLANK(N37), CONCATENATE("-",M37), CONCATENATE("-",P37,"-",N37))) -> 07Jul23-PRS-Gordon R-2 | V37: always setting 30ft or deeper
A38: 2023 | B38: Mini purse seine | C38: CCFS mini purse seine net | D38: 45114 | E38: 10:28 | F38: 45114 | G38: 10:38 | H38: Warriors Three | I38: 09:15 | J38: overcast, choppy | L38: CM, pfn crew? | N38: 3 | O38: Jap rock | P38: Jap Rock | Q38: 48.564944 | R38: -124.44083 | U38: =CONCATENATE(TEXT(F38,"ddmmmyy"),"-",IF(B38="Mini purse seine","PRS", IF(B38="PFN pole seine","POS", IF(B38="6' RST","RST", IF(B38="PFN beach seine","BS", IF(B38="IPT", "IPT", "FLAG"))))), IF(ISBLANK(N38), CONCATENATE("-",M38), CONCATENATE("-",P38,"-",N38))) -> 07Jul23-PRS-Jap Rock-3
A39: 2023 | B39: Mini purse seine | C39: CCFS mini purse seine net | D39: 45114 | E39: 11:19 | F39: 45114 | G39: 11:27 | H39: Warriors Three | I39: 09:15 | J39: overcast, choppy | L39: CM, pfn crew? | N39: 4 | O39: Thrasher Cove | P39: Thrasher | Q39: 48.554111 | R39: -124.46956 | U39: =CONCATENATE(TEXT(F39,"ddmmmyy"),"-",IF(B39="Mini purse seine","PRS", IF(B39="PFN pole seine","POS", IF(B39="6' RST","RST", IF(B39="PFN beach seine","BS", IF(B39="IPT", "IPT", "FLAG"))))), IF(ISBLANK(N39), CONCATENATE("-",M39), CONCATENATE("-",P39,"-",N39))) -> 07Jul23-PRS-Thrasher-4
A40: 2023 | B40: Mini purse seine | C40: CCFS mini purse seine net | D40: 45114 | E40: 12:07 | F40: 45114 | G40: 12:15 | H40: Warriors Three | I40: 09:15 | J40: overcast, choppy | L40: CM, pfn crew? | N40: 5 | O40: Mill Bay/BBR | P40: Mill Bay | Q40: 48.549444 | R40: -124.43972 | U40: =CONCATENATE(TEXT(F40,"ddmmmyy"),"-",IF(B40="Mini purse seine","PRS", IF(B40="PFN pole seine","POS", IF(B40="6' RST","RST", IF(B40="PFN beach seine","BS", IF(B40="IPT", "IPT", "FLAG"))))), IF(ISBLANK(N40), CONCATENATE("-",M40), CONCATENATE("-",P40,"-",N40))) -> 07Jul23-PRS-Mill Bay-5 | V40: set not fully enumerated
...

Sheet enviro
A1: usid | B1: date_enviros | C1: time_enviros | D1: depth_at_RST_m | E1: RST_RPMs | F1: RST_debris_load | G1: debris_type1 | H1: debris_type2 | I1: tennis_ball_time_min | J1: tennis_ball_distance_m | K1: air_temp | L1: bottom_depth | M1: depth_m | N1: water_temp | O1: salinity_psu | P1: conductivity_uS-cm | Q1: DO_mgL | R1: DO_perc | S1: comments
A2: 24Mar23-RST-N | B2: 45009 | C2: 09:00 | E2: 6.5 | F2: low | G2: misc organics | S2: test fishing after install
A3: 30Mar23-RST-N | B3: 45014 | C3: 17:00 | E3: 4.5 | S3: Reponsitioned RST slightly to fix RPMs after count of 4.5. Water lower, slower RPMs, trap closer to bank, occassionally rubbing ground.
A4: 30Mar23-RST-N | B4: 45015 | C4: 11:45 | E4: 6 | F4: low | G4: misc organics | H4: stick | M4: 0 | N4: 5.4 | R4: 98.2 | S4: Seal present
A5: 31Mar23-RST-N | B5: 45015 | C5: 18:40 | E5: 6 | S5: before trap set
A6: 31Mar23-RST-N | B6: 45016 | C6: 08:50 | E6: 5.5 | F6: low | G6: misc organics | H6: sticks | M6: 0 | N6: 5.4 | R6: 95.2 | S6: seal present in river
A7: 05Apr23-RST-N | B7: 45020 | C7: 18:20 | E7: 6
A8: 05Apr23-RST-N | B8: 45021 | C8: 11:50 | E8: 5.75 | F8: medium | G8: misc organics | M8: 0 | N8: 5.1 | R8: 95.8 | S8: bucket temp at end of sampling was 8C with 99.1% DO
A9: 06Apr23-RST-N | B9: 45021 | C9: 18:15 | E9: 5.75
A10: 06Apr23-RST-N | B10: 45022 | C10: 09:10 | E10: 5.75 | F10: medium | G10: misc organics | H10: stick | M10: 0 | N10: 5.2 | R10: 96.2
A11: 13Apr23-RST-N | B11: 45028 | C11: 18:00 | E11: 6
A12: 13Apr23-RST-N | B12: 45028 | C12: 09:00 | E12: 7 | F12: high | G12: misc organics | M12: 0 | N12: 5.8 | R12: 98.3
A13: 20Apr23-RST-N | B13: 45036 | C13: 08:45 | E13: 6 | F13: high | G13: misc organics | M13: 0 | N13: 5.1 | R13: 97.9 | S13: 764.3 mm Hg DO. installed DO meter
A14: 21Apr23-RST-N | B14: 45037 | C14: 08:45 | E14: 4 | F14: high | G14: misc organics | M14: 0 | N14: 5.3 | R14: 99.2 | S14: 769.3 mm Hg
A15: 21Apr23-RST-N | B15: 45036 | C15: 19:30 | E15: 5.5 | S15: 4 morts in trap screen from previous event
A16: 27Apr23-RST-N | B16: 45042 | C16: 06:00 | E16: 6+
A17: 27Apr23-RST-N | B17: 45043 | C17: 09:05 | E17: 6 | F17: medium | M17: 0 | N17: 6.5 | R17: 97.7
A18: 27Apr23-RST-D | B18: 45043 | C18: 10:55 | E18: 7 | M18: 0 | N18: 8.9 | R18: 101.3 | S18: 764.7 mm Hg
A19: 27Apr23-RST-D | B19: 45043 | C19: 10:55 | E19: 6.5 | F19: high | G19: misc organics | M19: 0 | N19: 8.9 | R19: 101.3 | S19: 764.7 mm Hg
A20: 28Apr23-RST-N | B20: 45043 | C20: 18:00 | E20: 7 | M20: 0 | N20: 6.9 | R20: 97.9
A21: 28Apr23-RST-N | B21: 45043 | C21: 08:35 | E21: 0 | F21: medium | M21: 0 | N21: 6.9 | R21: 97.9 | S21: cone not spinning on arrival. 762.0mm Hg
A22: 05May23-RST-N | B22: 45050 | C22: 0.6875 | E22: 5.25
A23: 05May23-RST-N | B23: 45051 | C23: 09:00 | E23: 4 | F23: medium | M23: 0 | N23: 8.3 | R23: 95.3 | S23: 755.4 mm Hg
A24: 05May23-POS-1 | B24: 45051 | C24: 0.42708333 | M24: 0 | N24: 13 | R24: 27.3 | S24: 755.6 mmHg; pole seine salvage from rod's drainage ditch
A25: 11May23-RST-N | B25: 45056 | C25: 0.67361111 | E25: 4.5
A26: 11May23-RST-N | B26: 45057 | C26: 09:05 | E26: 4 | F26: low | M26: 0 | N26: 9 | R26: 93 | S26: 764.1 mm Hg | T26: 13.62 seconds / 1.3 meters
A27: 02Jun23-RST-N | B27: 45078 | C27: 16:45 | E27: 3
A28: 02Jun23-RST-N | B28: 45079 | C28: 09:10 | E28: 0 | F28: low | M28: 0 | N28: 12.6 | R28: 87 | S28: 763.2 mm Hg. Cone not spinning on arrival, narrow part of cone shaft slipped out of sleeve. Flow rates(17.97, 15.56, 16.42, 20.48, 17.05, 15.67 seconds). Depth stick (1.2m, 1.4m, 1.5m)
A29: 02Jun23-HATLP-1 | B29: 45079 | C29: 0.66666667 | M29: 0 | N29: 16.7 | R29: 94.6 | S29: Turb 0.21 FNU; hatchery lake pen samples from fairy lake/SJ confl
A30: 02Jun23-HATLP-1 | B30: 45079 | C30: 0.66666667 | M30: 1 | N30: 16.7 | R30: 91.7 | S30: 0.20 FNU; hatchery lake pen samples from fairy lake/SJ confl
A31: 02Jun23-HATLP-1 | B31: 45079 | C31: 0.66666667 | M31: 2 | N31: 16.2 | R31: 92.1 | S31: 0.01 FNU; hatchery lake pen samples from fairy lake/SJ confl
A32: 08Jun23-RST-N | B32: 45085 | C32: 16:10 | E32: 2.875
A33: 08Jun23-RST-N | B33: 45085 | C33: 09:15 | E33: 1.25 | F33: low | G33: misc organics | M33: 0 | N33: 13.9 | R33: 83.3 | S33: mm Hg 759.7. Flow Rate (19.54, 19.32, 16.48, 16.82, 19.69 seconds). Depth stick (1.3m, 1.5m, 1.4m)
A34: 09Jun23-RST-N | B34: 45086 | C34: 15:35 | E34: 2.5
A35: 09Jun23-RST-N | B35: 45086 | C35: 09:00 | E35: 0 | F35: low | G35: big sticks | M35: 0 | N35: 13.5 | R35: 82.7 | S35: 761.3 mm Hg. Flow Rate (20.38, 14.68, 22.58, 19.00, 16.66 seconds). Depth stick (1.3m, 1.5m, 1.3m)
A36: 15Jun23-RST-N | B36: 45091 | C36: 16:30 | E36: 2
A37: 15Jun23-RST-N | B37: 45092 | C37: 08:45 | E37: 1.5 | F37: low | M37: 0 | N37: 13.6 | R37: 80.6 | S37: 764.7 mm Hg. Depth stick (1.3m, 1.4m, 1.5m)
A38: 16Jun23-RST-N | B38: 45092 | C38: 15:37 | E38: 1.7
A39: 16Jun23-RST-N | B39: 45093 | C39: 08:52 | E39: 1.4 | F39: low | G39: misc organics | H39: sticks | M39: 0 | N39: 13.6 | R39: 81.3 | S39: 764.8 mm Hg. Depth 1.25m
A40: 16Jun23-BS-1 | C40: 0.5 | M40: 0 | N40: 13.4 | R40: 110.7 | S40: 765.2 mmHg; logged in YSI
...

Sheet set_totals
A1: year | B1: gear | C1: usid | D1: date | E1: DOY | F1: species | G1: life_stage | H1: clip_status | I1: total_caught_incl_recaps | J1: total_caught_excl_recaps | K1: bismarck_recaps | L1: #_biosampled_released_alive_DYED | M1: #_biosampled_released_alive_UNDYED | N1: #_tallied_released_alive_DYED | O1: #_tallied_released_alive_UNDYED | P1: #_lethals | Q1: #_morts | R1: Comments
A2: 2023 | B2: 6' RST | C2: 24Mar23-RST-Night | D2: =DATEVALUE(LEFT(C2, SEARCH("-", C2) - 1)) -> 45009 | E2: =D2 - DATE(YEAR(D2), 1, 0) -> 83 | F2: rainbow | G2: parr | I2: =SUM(K2:Q2) -> 2 | J2: =SUM(L2:Q2) -> 2 | K2: 0 | M2: 1 | O2: 1 | R2: test fish after install
A3: 2023 | B3: 6' RST | C3: 24Mar23-RST-Night | D3: =DATEVALUE(LEFT(C3, SEARCH("-", C3) - 1)) -> 45009 | E3: =D3 - DATE(YEAR(D3), 1, 0) -> 83 | F3: chum | G3: fry | I3: =SUM(K3:Q3) -> 8 | J3: =SUM(L3:Q3) -> 8 | K3: 0 | M3: 4 | Q3: 4 | R3: test fish after install - includes practice sample mort
A4: 2023 | B4: 6' RST | C4: 24Mar23-RST-Night | D4: =DATEVALUE(LEFT(C4, SEARCH("-", C4) - 1)) -> 45009 | E4: =D4 - DATE(YEAR(D4), 1, 0) -> 83 | F4: coho | G4: fry | I4: =SUM(K4:Q4) -> 31 | J4: =SUM(L4:Q4) -> 31 | K4: 0 | M4: 27 | Q4: 4 | R4: test fish after install
A5: 2023 | B5: 6' RST | C5: 24Mar23-RST-Night | D5: =DATEVALUE(LEFT(C5, SEARCH("-", C5) - 1)) -> 45009 | E5: =D5 - DATE(YEAR(D5), 1, 0) -> 83 | F5: chinook | G5: fry | H5: unclipped | I5: =SUM(K5:Q5) -> 4 | J5: =SUM(L5:Q5) -> 4 | K5: 0 | M5: 3 | Q5: 1 | R5: test fish after install
A6: 2023 | B6: 6' RST | C6: 24Mar23-RST-Night | D6: =DATEVALUE(LEFT(C6, SEARCH("-", C6) - 1)) -> 45009 | E6: =D6 - DATE(YEAR(D6), 1, 0) -> 83 | F6: stickleback | I6: =SUM(K6:Q6) -> 2 | J6: =SUM(L6:Q6) -> 2 | K6: 0 | O6: 2 | R6: test fish after install
A7: 2023 | B7: 6' RST | C7: 24Mar23-RST-Night | D7: =DATEVALUE(LEFT(C7, SEARCH("-", C7) - 1)) -> 45009 | E7: =D7 - DATE(YEAR(D7), 1, 0) -> 83 | F7: sculpin | I7: =SUM(K7:Q7) -> 1 | J7: =SUM(L7:Q7) -> 1 | K7: 0 | O7: 1 | R7: test fish after install
A8: 2023 | B8: 6' RST | C8: 24Mar23-RST-Night | D8: =DATEVALUE(LEFT(C8, SEARCH("-", C8) - 1)) -> 45009 | E8: =D8 - DATE(YEAR(D8), 1, 0) -> 83 | F8: coho | G8: smolt | I8: =SUM(K8:Q8) -> 7 | J8: =SUM(L8:Q8) -> 7 | K8: 0 | M8: 7 | R8: test fish after install
A9: 2023 | B9: 6' RST | C9: 30Mar23-RST-Night | D9: =DATEVALUE(LEFT(C9, SEARCH("-", C9) - 1)) -> 45015 | E9: =D9 - DATE(YEAR(D9), 1, 0) -> 89 | F9: coho | G9: fry | I9: =SUM(K9:Q9) -> 148 | J9: =SUM(L9:Q9) -> 148 | K9: 0 | M9: 30 | O9: 96 | Q9: 22 | R9: 1 coho fry in column A is a mort. Most morts due to grate at back of trap being put in backwards and gilled fish.
A10: 2023 | B10: 6' RST | C10: 30Mar23-RST-Night | D10: =DATEVALUE(LEFT(C10, SEARCH("-", C10) - 1)) -> 45015 | E10: =D10 - DATE(YEAR(D10), 1, 0) -> 89 | F10: chum | G10: fry | I10: =SUM(K10:Q10) -> 52 | J10: =SUM(L10:Q10) -> 52 | K10: 0 | M10: 30 | O10: 16 | Q10: 6 | R10: Most morts due to grate at back of trap being put in backwards and gilled fish.
A11: 2023 | B11: 6' RST | C11: 30Mar23-RST-Night | D11: =DATEVALUE(LEFT(C11, SEARCH("-", C11) - 1)) -> 45015 | E11: =D11 - DATE(YEAR(D11), 1, 0) -> 89 | F11: chinook | G11: fry | H11: unclipped | I11: =SUM(K11:Q11) -> 29 | J11: =SUM(L11:Q11) -> 29 | K11: 0 | M11: 28 | Q11: 1 | R11: Most morts due to grate at back of trap being put in backwards and gilled fish.
A12: 2023 | B12: 6' RST | C12: 30Mar23-RST-Night | D12: =DATEVALUE(LEFT(C12, SEARCH("-", C12) - 1)) -> 45015 | E12: =D12 - DATE(YEAR(D12), 1, 0) -> 89 | F12: sculpin | I12: =SUM(K12:Q12) -> 1 | J12: =SUM(L12:Q12) -> 1 | K12: 0 | O12: 1
A13: 2023 | B13: 6' RST | C13: 30Mar23-RST-Night | D13: =DATEVALUE(LEFT(C13, SEARCH("-", C13) - 1)) -> 45015 | E13: =D13 - DATE(YEAR(D13), 1, 0) -> 89 | F13: stickleback | I13: =SUM(K13:Q13) -> 1 | J13: =SUM(L13:Q13) -> 1 | K13: 0 | Q13: 1
A14: 2023 | B14: 6' RST | C14: 30Mar23-RST-Night | D14: =DATEVALUE(LEFT(C14, SEARCH("-", C14) - 1)) -> 45015 | E14: =D14 - DATE(YEAR(D14), 1, 0) -> 89 | F14: coho | G14: smolt | I14: =SUM(K14:Q14) -> 2 | J14: =SUM(L14:Q14) -> 2 | K14: 0 | M14: 2 | R14: 1 smolt in column A is a mort post-processing
A15: 2023 | B15: 6' RST | C15: 30Mar23-RST-Night | D15: =DATEVALUE(LEFT(C15, SEARCH("-", C15) - 1)) -> 45015 | E15: =D15 - DATE(YEAR(D15), 1, 0) -> 89 | F15: rainbow | G15: parr | I15: =SUM(K15:Q15) -> 1 | J15: =SUM(L15:Q15) -> 1 | K15: 0 | M15: 1
A16: 2023 | B16: 6' RST | C16: 30Mar23-RST-Night | D16: =DATEVALUE(LEFT(C16, SEARCH("-", C16) - 1)) -> 45015 | E16: =D16 - DATE(YEAR(D16), 1, 0) -> 89 | F16: rainbow | G16: fry | I16: =SUM(K16:Q16) -> 1 | J16: =SUM(L16:Q16) -> 1 | K16: 0 | M16: 1
A17: 2023 | B17: 6' RST | C17: 31Mar23-RST-Night | D17: =DATEVALUE(LEFT(C17, SEARCH("-", C17) - 1)) -> 45016 | E17: =D17 - DATE(YEAR(D17), 1, 0) -> 90 | F17: roughskin newt | I17: =SUM(K17:Q17) -> 1 | J17: =SUM(L17:Q17) -> 1 | K17: 0 | O17: 1
A18: 2023 | B18: 6' RST | C18: 31Mar23-RST-Night | D18: =DATEVALUE(LEFT(C18, SEARCH("-", C18) - 1)) -> 45016 | E18: =D18 - DATE(YEAR(D18), 1, 0) -> 90 | F18: western toadlet | I18: =SUM(K18:Q18) -> 1 | J18: =SUM(L18:Q18) -> 1 | K18: 0 | O18: 1
A19: 2023 | B19: 6' RST | C19: 31Mar23-RST-Night | D19: =DATEVALUE(LEFT(C19, SEARCH("-", C19) - 1)) -> 45016 | E19: =D19 - DATE(YEAR(D19), 1, 0) -> 90 | F19: lamprey | I19: =SUM(K19:Q19) -> 2 | J19: =SUM(L19:Q19) -> 2 | K19: 0 | O19: 2 | R19: Ammocete larvae. Photos taken.
A20: 2023 | B20: 6' RST | C20: 31Mar23-RST-Night | D20: =DATEVALUE(LEFT(C20, SEARCH("-", C20) - 1)) -> 45016 | E20: =D20 - DATE(YEAR(D20), 1, 0) -> 90 | F20: sculpin | I20: =SUM(K20:Q20) -> 2 | J20: =SUM(L20:Q20) -> 2 | K20: 0 | O20: 1 | Q20: 1
A21: 2023 | B21: 6' RST | C21: 31Mar23-RST-Night | D21: =DATEVALUE(LEFT(C21, SEARCH("-", C21) - 1)) -> 45016 | E21: =D21 - DATE(YEAR(D21), 1, 0) -> 90 | F21: coho | G21: fry | I21: =SUM(K21:Q21) -> 253 | J21: =SUM(L21:Q21) -> 253 | K21: 0 | M21: 30 | O21: 221 | Q21: 2
A22: 2023 | B22: 6' RST | C22: 31Mar23-RST-Night | D22: =DATEVALUE(LEFT(C22, SEARCH("-", C22) - 1)) -> 45016 | E22: =D22 - DATE(YEAR(D22), 1, 0) -> 90 | F22: chum | G22: fry | I22: =SUM(K22:Q22) -> 83 | J22: =SUM(L22:Q22) -> 83 | K22: 0 | M22: 27 | O22: 55 | Q22: 1
A23: 2023 | B23: 6' RST | C23: 31Mar23-RST-Night | D23: =DATEVALUE(LEFT(C23, SEARCH("-", C23) - 1)) -> 45016 | E23: =D23 - DATE(YEAR(D23), 1, 0) -> 90 | F23: coho | G23: smolt | I23: =SUM(K23:Q23) -> 6 | J23: =SUM(L23:Q23) -> 6 | K23: 0 | M23: 6
A24: 2023 | B24: 6' RST | C24: 31Mar23-RST-Night | D24: =DATEVALUE(LEFT(C24, SEARCH("-", C24) - 1)) -> 45016 | E24: =D24 - DATE(YEAR(D24), 1, 0) -> 90 | F24: chinook | G24: fry | H24: unclipped | I24: =SUM(K24:Q24) -> 33 | J24: =SUM(L24:Q24) -> 33 | K24: 0 | M24: 30 | O24: 3
A25: 2023 | B25: 6' RST | C25: 31Mar23-RST-Night | D25: =DATEVALUE(LEFT(C25, SEARCH("-", C25) - 1)) -> 45016 | E25: =D25 - DATE(YEAR(D25), 1, 0) -> 90 | F25: rainbow | G25: parr | I25: =SUM(K25:Q25) -> 1 | J25: =SUM(L25:Q25) -> 1 | K25: 0 | M25: 1
A26: 2023 | B26: 6' RST | C26: 05Apr23-RST-Night | D26: =DATEVALUE(LEFT(C26, SEARCH("-", C26) - 1)) -> 45021 | E26: =D26 - DATE(YEAR(D26), 1, 0) -> 95 | F26: coho | G26: fry | I26: =SUM(K26:Q26) -> 143 | J26: =SUM(L26:Q26) -> 143 | K26: 0 | M26: 30 | O26: 113
A27: 2023 | B27: 6' RST | C27: 05Apr23-RST-Night | D27: =DATEVALUE(LEFT(C27, SEARCH("-", C27) - 1)) -> 45021 | E27: =D27 - DATE(YEAR(D27), 1, 0) -> 95 | F27: chum | G27: fry | I27: =SUM(K27:Q27) -> 38 | J27: =SUM(L27:Q27) -> 38 | K27: 0 | M27: 30 | O27: 8 | R27: 1 chum mort post-processing found in bin
A28: 2023 | B28: 6' RST | C28: 05Apr23-RST-Night | D28: =DATEVALUE(LEFT(C28, SEARCH("-", C28) - 1)) -> 45021 | E28: =D28 - DATE(YEAR(D28), 1, 0) -> 95 | F28: chinook | G28: fry | H28: unclipped | I28: =SUM(K28:Q28) -> 23 | J28: =SUM(L28:Q28) -> 23 | K28: 0 | M28: 23
A29: 2023 | B29: 6' RST | C29: 05Apr23-RST-Night | D29: =DATEVALUE(LEFT(C29, SEARCH("-", C29) - 1)) -> 45021 | E29: =D29 - DATE(YEAR(D29), 1, 0) -> 95 | F29: coho | G29: smolt | I29: =SUM(K29:Q29) -> 10 | J29: =SUM(L29:Q29) -> 10 | K29: 0 | M29: 10
A30: 2023 | B30: 6' RST | C30: 06Apr23-RST-Night | D30: =DATEVALUE(LEFT(C30, SEARCH("-", C30) - 1)) -> 45022 | E30: =D30 - DATE(YEAR(D30), 1, 0) -> 96 | F30: chinook | G30: fry | H30: unclipped | I30: =SUM(K30:Q30) -> 27 | J30: =SUM(L30:Q30) -> 27 | K30: 0 | M30: 20 | P30: 7
A31: 2023 | B31: 6' RST | C31: 06Apr23-RST-Night | D31: =DATEVALUE(LEFT(C31, SEARCH("-", C31) - 1)) -> 45022 | E31: =D31 - DATE(YEAR(D31), 1, 0) -> 96 | F31: coho | G31: fry | I31: =SUM(K31:Q31) -> 178 | J31: =SUM(L31:Q31) -> 178 | K31: 0 | M31: 30 | O31: 142 | Q31: 6
A32: 2023 | B32: 6' RST | C32: 06Apr23-RST-Night | D32: =DATEVALUE(LEFT(C32, SEARCH("-", C32) - 1)) -> 45022 | E32: =D32 - DATE(YEAR(D32), 1, 0) -> 96 | F32: chum | G32: fry | I32: =SUM(K32:Q32) -> 9 | J32: =SUM(L32:Q32) -> 9 | K32: 0 | M32: 9
A33: 2023 | B33: 6' RST | C33: 06Apr23-RST-Night | D33: =DATEVALUE(LEFT(C33, SEARCH("-", C33) - 1)) -> 45022 | E33: =D33 - DATE(YEAR(D33), 1, 0) -> 96 | F33: coho | G33: smolt | I33: =SUM(K33:Q33) -> 2 | J33: =SUM(L33:Q33) -> 2 | K33: 0 | M33: 2
A34: 2023 | B34: 6' RST | C34: 06Apr23-RST-Night | D34: =DATEVALUE(LEFT(C34, SEARCH("-", C34) - 1)) -> 45022 | E34: =D34 - DATE(YEAR(D34), 1, 0) -> 96 | F34: rainbow | G34: parr | I34: =SUM(K34:Q34) -> 1 | J34: =SUM(L34:Q34) -> 1 | K34: 0 | M34: 1
A35: 2023 | B35: 6' RST | C35: 06Apr23-RST-Night | D35: =DATEVALUE(LEFT(C35, SEARCH("-", C35) - 1)) -> 45022 | E35: =D35 - DATE(YEAR(D35), 1, 0) -> 96 | F35: roughskin newt | I35: =SUM(K35:Q35) -> 1 | J35: =SUM(L35:Q35) -> 1 | K35: 0 | O35: 1
A36: 2023 | B36: 6' RST | C36: 06Apr23-RST-Night | D36: =DATEVALUE(LEFT(C36, SEARCH("-", C36) - 1)) -> 45022 | E36: =D36 - DATE(YEAR(D36), 1, 0) -> 96 | F36: western toadlet | I36: =SUM(K36:Q36) -> 2 | J36: =SUM(L36:Q36) -> 2 | K36: 0 | O36: 2 | R36: 1 may be a mort
A37: 2023 | B37: 6' RST | C37: 13Apr23-RST-Night | D37: =DATEVALUE(LEFT(C37, SEARCH("-", C37) - 1)) -> 45029 | E37: =D37 - DATE(YEAR(D37), 1, 0) -> 103 | F37: coho | G37: fry | I37: =SUM(K37:Q37) -> 228 | J37: =SUM(L37:Q37) -> 228 | K37: 0 | M37: 30 | O37: 74 | Q37: 124 | R37: 3 or more dozen morts still in funnel grate
A38: 2023 | B38: 6' RST | C38: 13Apr23-RST-Night | D38: =DATEVALUE(LEFT(C38, SEARCH("-", C38) - 1)) -> 45029 | E38: =D38 - DATE(YEAR(D38), 1, 0) -> 103 | F38: coho | G38: smolt | I38: =SUM(K38:Q38) -> 21 | J38: =SUM(L38:Q38) -> 21 | K38: 0 | M38: 21
A39: 2023 | B39: 6' RST | C39: 13Apr23-RST-Night | D39: =DATEVALUE(LEFT(C39, SEARCH("-", C39) - 1)) -> 45029 | E39: =D39 - DATE(YEAR(D39), 1, 0) -> 103 | F39: cutthroat | G39: parr | I39: =SUM(K39:Q39) -> 2 | J39: =SUM(L39:Q39) -> 2 | K39: 0 | M39: 2
A40: 2023 | B40: 6' RST | C40: 20Apr23-RST-Night | D40: =DATEVALUE(LEFT(C40, SEARCH("-", C40) - 1)) -> 45036 | E40: =D40 - DATE(YEAR(D40), 1, 0) -> 110 | F40: coho | G40: fry | I40: =SUM(K40:Q40) -> 139 | J40: =SUM(L40:Q40) -> 139 | K40: 0 | M40: 30 | O40: 80 | Q40: =16+13 -> 29
...

Sheet biosampling
A1: year | B1: gear | C1: usid | D1: date | E1: DOY | F1: species | G1: life_stage | H1: length | I1: height | J1: weight | K1: ad_clip | L1: cwt | M1: hatchery_origin | N1: lethal_tag_no | O1: RNA_vial | P1: DNA_vial | Q1: frozen_lethal | R1: company_st_analysis | S1: stomach_results_received | T1: SF_hemo | U1: SF_erosion_rot | V1: SF_finmouth_rot | W1: SF_ulcer | X1: S_xs_mucous | Y1: G_pale | Z1: G_erosion | AA1: G_whitespots | AB1: other_clinical | AC1: n_motile_sealice | AD1: comments | AE1: condition_factor_QC | AF1: sampler | AG1: sampling_date | AH1: lab_dna_clip_yn | AI1: lab_gill_clip_yn | AJ1: cwt_yn | AK1: cwt_code | AL1: adipose_clip_yn | AM1: lab_length_mm | AN1: lab_height_mm | AO1: lab_weight_g | AP1: whole_muscle | AQ1: otolith_box | AR1: otolith_vial | AS1: scale_book | AT1: scale_cell | AU1: stomach_bag | AV1: mgl_gill_yn | AW1: mgl_muscle_yn | AX1: mgl_liver_yn | AY1: mgl_spleen_yn | AZ1: mgl_antkidney_yn | BA1: mgl_heart_yn | BB1: mgl_brain_yn | BC1: mgl_stomach_swab_yn | BD1: biotoxin_gill_yn | BE1: biotoxin_liver_yn | BF1: oto_sent_to_IOS? | BG1: comments_sampling | BH1: DNA_Submission_File
A2: 2023 | B2: 6' RST | C2: 24Mar23-RST-N | D2: =DATEVALUE(LEFT(C2, SEARCH("-", C2) - 1)) -> 45009 | E2: =D2 - DATE(YEAR(D2), 1, 0) -> 83 | F2: chum | G2: fry | H2: 42 | J2: 0.58 | K2: N | M2: N | Q2: N | T2: N | U2: N | V2: N | W2: N | X2: N | Y2: N | Z2: N | AA2: N | AB2: N | AD2: mort - practice sample (NOT INCLUDED IN SAMPLED TOTAL, included in morts total) | AE2: =IF(J2="", "", 100000*(J2/(H2^3))) -> 0.78285282
A3: 2023 | B3: 6' RST | C3: 24Mar23-RST-N | D3: =DATEVALUE(LEFT(C3, SEARCH("-", C3) - 1)) -> 45009 | E3: =D3 - DATE(YEAR(D3), 1, 0) -> 83 | F3: coho | G3: fry | H3: 38 | J3: 0.67 | K3: N | M3: N | Q3: N | T3: N | U3: N | V3: N | W3: N | X3: N | Y3: N | Z3: N | AA3: N | AB3: N | AE3: =IF(J3="", "", 100000*(J3/(H3^3))) -> 1.2210235
A4: 2023 | B4: 6' RST | C4: 24Mar23-RST-N | D4: =DATEVALUE(LEFT(C4, SEARCH("-", C4) - 1)) -> 45009 | E4: =D4 - DATE(YEAR(D4), 1, 0) -> 83 | F4: chinook | G4: fry | H4: 41 | J4: 0.69 | K4: N | M4: N | Q4: N | T4: N | U4: N | V4: N | W4: N | X4: N | Y4: N | Z4: N | AA4: N | AB4: N | AE4: =IF(J4="", "", 100000*(J4/(H4^3))) -> 1.0011462
A5: 2023 | B5: 6' RST | C5: 24Mar23-RST-N | D5: =DATEVALUE(LEFT(C5, SEARCH("-", C5) - 1)) -> 45009 | E5: =D5 - DATE(YEAR(D5), 1, 0) -> 83 | F5: coho | G5: smolt | H5: 70 | J5: 3.72 | K5: N | M5: N | Q5: N | T5: N | U5: N | V5: N | W5: N | X5: N | Y5: N | Z5: N | AA5: N | AB5: N | AE5: =IF(J5="", "", 100000*(J5/(H5^3))) -> 1.0845481
A6: 2023 | B6: 6' RST | C6: 24Mar23-RST-N | D6: =DATEVALUE(LEFT(C6, SEARCH("-", C6) - 1)) -> 45009 | E6: =D6 - DATE(YEAR(D6), 1, 0) -> 83 | F6: coho | G6: fry | H6: 36 | J6: 0.48 | K6: N | M6: N | Q6: N | T6: N | U6: N | V6: N | W6: N | X6: N | Y6: N | Z6: N | AA6: N | AB6: N | AE6: =IF(J6="", "", 100000*(J6/(H6^3))) -> 1.0288066
A7: 2023 | B7: 6' RST | C7: 24Mar23-RST-N | D7: =DATEVALUE(LEFT(C7, SEARCH("-", C7) - 1)) -> 45009 | E7: =D7 - DATE(YEAR(D7), 1, 0) -> 83 | F7: coho | G7: smolt | H7: 71 | J7: 3.92 | K7: N | M7: N | Q7: N | T7: N | U7: N | V7: N | W7: N | X7: N | Y7: N | Z7: N | AA7: N | AB7: N | AE7: =IF(J7="", "", 100000*(J7/(H7^3))) -> 1.0952443
A8: 2023 | B8: 6' RST | C8: 24Mar23-RST-N | D8: =DATEVALUE(LEFT(C8, SEARCH("-", C8) - 1)) -> 45009 | E8: =D8 - DATE(YEAR(D8), 1, 0) -> 83 | F8: coho | G8: fry | H8: 43 | J8: 0.74 | K8: N | M8: N | Q8: N | T8: N | U8: N | V8: N | W8: N | X8: N | Y8: N | Z8: N | AA8: N | AB8: N | AE8: =IF(J8="", "", 100000*(J8/(H8^3))) -> 0.93073566
A9: 2023 | B9: 6' RST | C9: 24Mar23-RST-N | D9: =DATEVALUE(LEFT(C9, SEARCH("-", C9) - 1)) -> 45009 | E9: =D9 - DATE(YEAR(D9), 1, 0) -> 83 | F9: coho | G9: fry | H9: 42 | J9: 0.69 | K9: N | M9: N | Q9: N | T9: N | U9: N | V9: N | W9: N | X9: N | Y9: N | Z9: N | AA9: N | AB9: N | AE9: =IF(J9="", "", 100000*(J9/(H9^3))) -> 0.93132491
A10: 2023 | B10: 6' RST | C10: 24Mar23-RST-N | D10: =DATEVALUE(LEFT(C10, SEARCH("-", C10) - 1)) -> 45009 | E10: =D10 - DATE(YEAR(D10), 1, 0) -> 83 | F10: coho | G10: fry | H10: 36 | J10: 0.48 | K10: N | M10: N | Q10: N | T10: N | U10: N | V10: N | W10: N | X10: N | Y10: N | Z10: N | AA10: N | AB10: N | AE10: =IF(J10="", "", 100000*(J10/(H10^3))) -> 1.0288066
A11: 2023 | B11: 6' RST | C11: 24Mar23-RST-N | D11: =DATEVALUE(LEFT(C11, SEARCH("-", C11) - 1)) -> 45009 | E11: =D11 - DATE(YEAR(D11), 1, 0) -> 83 | F11: coho | G11: fry | H11: 40 | J11: 0.7 | K11: N | M11: N | Q11: N | T11: N | U11: N | V11: N | W11: N | X11: N | Y11: N | Z11: N | AA11: N | AB11: N | AE11: =IF(J11="", "", 100000*(J11/(H11^3))) -> 1.09375
A12: 2023 | B12: 6' RST | C12: 24Mar23-RST-N | D12: =DATEVALUE(LEFT(C12, SEARCH("-", C12) - 1)) -> 45009 | E12: =D12 - DATE(YEAR(D12), 1, 0) -> 83 | F12: coho | G12: fry | H12: 39 | J12: 0.48 | K12: N | M12: N | Q12: N | T12: N | U12: N | V12: N | W12: N | X12: N | Y12: N | Z12: N | AA12: N | AB12: N | AE12: =IF(J12="", "", 100000*(J12/(H12^3))) -> 0.80918424
A13: 2023 | B13: 6' RST | C13: 24Mar23-RST-N | D13: =DATEVALUE(LEFT(C13, SEARCH("-", C13) - 1)) -> 45009 | E13: =D13 - DATE(YEAR(D13), 1, 0) -> 83 | F13: rainbow | G13: parr | H13: 80 | J13: 5.47 | K13: N | M13: N | Q13: N | T13: N | U13: N | V13: N | W13: N | X13: N | Y13: N | Z13: N | AA13: N | AB13: N | AE13: =IF(J13="", "", 100000*(J13/(H13^3))) -> 1.0683594
A14: 2023 | B14: 6' RST | C14: 24Mar23-RST-N | D14: =DATEVALUE(LEFT(C14, SEARCH("-", C14) - 1)) -> 45009 | E14: =D14 - DATE(YEAR(D14), 1, 0) -> 83 | F14: coho | G14: fry | H14: 37 | J14: 0.55 | K14: N | M14: N | Q14: N | T14: N | U14: N | V14: N | W14: N | X14: N | Y14: N | Z14: N | AA14: N | AB14: N | AE14: =IF(J14="", "", 100000*(J14/(H14^3))) -> 1.0858192
... A63: 2023 | B63: 6' RST | C63: 30Mar23-RST-N | D63: =DATEVALUE(LEFT(C63, SEARCH("-", C63) - 1)) -> 45015 | E63: =D63 - DATE(YEAR(D63), 1, 0) -> 89 | F63: chum | G63: fry | H63: 38 | J63: 0.4 | K63: N | M63: N | Q63: N | T63: N | U63: N | V63: N | W63: N | X63: N | Y63: N | Z63: N | AA63: N | AB63: N | AE63: =IF(J63="", "", 100000*(J63/(H63^3))) -> 0.72896924
A64: 2023 | B64: 6' RST | C64: 30Mar23-RST-N | D64: =DATEVALUE(LEFT(C64, SEARCH("-", C64) - 1)) -> 45015 | E64: =D64 - DATE(YEAR(D64), 1, 0) -> 89 | F64: chum | G64: fry | H64: 39 | J64: 0.4 | K64: N | M64: N | Q64: N | T64: N | U64: N | V64: N | W64: N | X64: N | Y64: N | Z64: N | AA64: N | AB64: Y | AD64: gill exposed | AE64: =IF(J64="", "", 100000*(J64/(H64^3))) -> 0.6743202
A65: 2023 | B65: 6' RST | C65: 30Mar23-RST-N | D65: =DATEVALUE(LEFT(C65, SEARCH("-", C65) - 1)) -> 45015 | E65: =D65 - DATE(YEAR(D65), 1, 0) -> 89 | F65: chum | G65: fry | H65: 40 | J65: 0.48 | K65: N | M65: N | Q65: N | T65: N | U65: N | V65: N | W65: N | X65: N | Y65: N | Z65: N | AA65: N | AB65: N | AE65: =IF(J65="", "", 100000*(J65/(H65^3))) -> 0.75
A66: 2023 | B66: 6' RST | C66: 30Mar23-RST-N | D66: =DATEVALUE(LEFT(C66, SEARCH("-", C66) - 1)) -> 45015 | E66: =D66 - DATE(YEAR(D66), 1, 0) -> 89 | F66: chum | G66: fry | H66: 41 | J66: 0.51 | K66: N | M66: N | Q66: N | T66: N | U66: N | V66: N | W66: N | X66: N | Y66: N | Z66: N | AA66: N | AB66: N | AE66: =IF(J66="", "", 100000*(J66/(H66^3))) -> 0.73997766
A67: 2023 | B67: 6' RST | C67: 30Mar23-RST-N | D67: =DATEVALUE(LEFT(C67, SEARCH("-", C67) - 1)) -> 45015 | E67: =D67 - DATE(YEAR(D67), 1, 0) -> 89 | F67: chum | G67: fry | H67: 37 | J67: 0.43 | K67: N | M67: N | Q67: N | T67: N | U67: N | V67: N | W67: N | X67: N | Y67: N | Z67: N | AA67: N | AB67: N | AE67: =IF(J67="", "", 100000*(J67/(H67^3))) -> 0.84891319
A68: 2023 | B68: 6' RST | C68: 30Mar23-RST-N | D68: =DATEVALUE(LEFT(C68, SEARCH("-", C68) - 1)) -> 45015 | E68: =D68 - DATE(YEAR(D68), 1, 0) -> 89 | F68: chum | G68: fry | H68: 39 | J68: 0.47 | K68: N | M68: N | Q68: N | T68: N | U68: N | V68: N | W68: N | X68: N | Y68: N | Z68: N | AA68: N | AB68: N | AE68: =IF(J68="", "", 100000*(J68/(H68^3))) -> 0.79232624
A69: 2023 | B69: 6' RST | C69: 30Mar23-RST-N | D69: =DATEVALUE(LEFT(C69, SEARCH("-", C69) - 1)) -> 45015 | E69: =D69 - DATE(YEAR(D69), 1, 0) -> 89 | F69: chum | G69: fry | H69: 40 | J69: 0.43 | K69: N | M69: N | Q69: N | T69: N | U69: N | V69: N | W69: N | X69: N | Y69: N | Z69: N | AA69: N | AB69: N | AE69: =IF(J69="", "", 100000*(J69/(H69^3))) -> 0.671875
A70: 2023 | B70: 6' RST | C70: 30Mar23-RST-N | D70: =DATEVALUE(LEFT(C70, SEARCH("-", C70) - 1)) -> 45015 | E70: =D70 - DATE(YEAR(D70), 1, 0) -> 89 | F70: chum | G70: fry | H70: 40 | J70: 0.5 | K70: N | M70: N | Q70: N | T70: N | U70: N | V70: N | W70: N | X70: N | Y70: N | Z70: N | AA70: N | AB70: N | AE70: =IF(J70="", "", 100000*(J70/(H70^3))) -> 0.78125
A71: 2023 | B71: 6' RST | C71: 30Mar23-RST-N | D71: =DATEVALUE(LEFT(C71, SEARCH("-", C71) - 1)) -> 45015 | E71: =D71 - DATE(YEAR(D71), 1, 0) -> 89 | F71: chum | G71: fry | H71: 42 | J71: 0.48 | K71: N | M71: N | Q71: N | T71: N | U71: N | V71: N | W71: N | X71: N | Y71: N | Z71: N | AA71: N | AB71: N | AE71: =IF(J71="", "", 100000*(J71/(H71^3))) -> 0.6478782
A72: 2023 | B72: 6' RST | C72: 30Mar23-RST-N | D72: =DATEVALUE(LEFT(C72, SEARCH("-", C72) - 1)) -> 45015 | E72: =D72 - DATE(YEAR(D72), 1, 0) -> 89 | F72: chum | G72: fry | H72: 39 | J72: 0.41 | K72: N | M72: N | Q72: N | T72: N | U72: N | V72: N | W72: N | X72: N | Y72: N | Z72: N | AA72: N | AB72: Y | AD72: missing eye | AE72: =IF(J72="", "", 100000*(J72/(H72^3))) -> 0.69117821
A73: 2023 | B73: 6' RST | C73: 30Mar23-RST-N | D73: =DATEVALUE(LEFT(C73, SEARCH("-", C73) - 1)) -> 45015 | E73: =D73 - DATE(YEAR(D73), 1, 0) -> 89 | F73: chum | G73: fry | H73: 41 | J73: 0.5 | K73: N | M73: N | Q73: N | T73: N | U73: N | V73: N | W73: N | X73: N | Y73: N | Z73: N | AA73: N | AB73: N | AE73: =IF(J73="", "", 100000*(J73/(H73^3))) -> 0.72546829
A74: 2023 | B74: 6' RST | C74: 30Mar23-RST-N | D74: =DATEVALUE(LEFT(C74, SEARCH("-", C74) - 1)) -> 45015 | E74: =D74 - DATE(YEAR(D74), 1, 0) -> 89 | F74: coho | G74: fry | H74: 36 | J74: 0.48 | K74: N | M74: N | Q74: N | T74: N | U74: N | V74: N | W74: N | X74: N | Y74: N | Z74: N | AA74: N | AB74: N | AD74: mort | AE74: =IF(J74="", "", 100000*(J74/(H74^3))) -> 1.0288066
A75: 2023 | B75: 6' RST | C75: 30Mar23-RST-N | D75: =DATEVALUE(LEFT(C75, SEARCH("-", C75) - 1)) -> 45015 | E75: =D75 - DATE(YEAR(D75), 1, 0) -> 89 | F75: coho | G75: fry | H75: 36 | J75: 0.43 | K75: N | M75: N | Q75: N | T75: N | U75: N | V75: N | W75: N | X75: N | Y75: N | Z75: N | AA75: N | AB75: N | AE75: =IF(J75="", "", 100000*(J75/(H75^3))) -> 0.92163923
A76: 2023 | B76: 6' RST | C76: 30Mar23-RST-N | D76: =DATEVALUE(LEFT(C76, SEARCH("-", C76) - 1)) -> 45015 | E76: =D76 - DATE(YEAR(D76), 1, 0) -> 89 | F76: coho | G76: fry | H76: 37 | J76: 0.46 | K76: N | M76: N | Q76: N | T76: N | U76: N | V76: N | W76: N | X76: N | Y76: N | Z76: N | AA76: N | AB76: N | AE76: =IF(J76="", "", 100000*(J76/(H76^3))) -> 0.9081397
A77: 2023 | B77: 6' RST | C77: 30Mar23-RST-N | D77: =DATEVALUE(LEFT(C77, SEARCH("-", C77) - 1)) -> 45015 | E77: =D77 - DATE(YEAR(D77), 1, 0) -> 89 | F77: coho | G77: fry | H77: 37 | J77: 0.45 | K77: N | M77: N | Q77: N | T77: N | U77: N | V77: N | W77: N | X77: N | Y77: N | Z77: N | AA77: N | AB77: N | AE77: =IF(J77="", "", 100000*(J77/(H77^3))) -> 0.88839753
A78: 2023 | B78: 6' RST | C78: 30Mar23-RST-N | D78: =DATEVALUE(LEFT(C78, SEARCH("-", C78) - 1)) -> 45015 | E78: =D78 - DATE(YEAR(D78), 1, 0) -> 89 | F78: coho | G78: fry | H78: 36 | J78: 0.44 | K78: N | M78: N | Q78: N | T78: N | U78: N | V78: N | W78: N | X78: N | Y78: N | Z78: N | AA78: N | AB78: N | AE78: =IF(J78="", "", 100000*(J78/(H78^3))) -> 0.9430727
A79: 2023 | B79: 6' RST | C79: 30Mar23-RST-N | D79: =DATEVALUE(LEFT(C79, SEARCH("-", C79) - 1)) -> 45015 | E79: =D79 - DATE(YEAR(D79), 1, 0) -> 89 | F79: coho | G79: fry | H79: 38 | J79: 0.44 | K79: N | M79: N | Q79: N | T79: N | U79: N | V79: N | W79: N | X79: N | Y79: N | Z79: N | AA79: N | AB79: N | AE79: =IF(J79="", "", 100000*(J79/(H79^3))) -> 0.80186616
A80: 2023 | B80: 6' RST | C80: 30Mar23-RST-N | D80: =DATEVALUE(LEFT(C80, SEARCH("-", C80) - 1)) -> 45015 | E80: =D80 - DATE(YEAR(D80), 1, 0) -> 89 | F80: coho | G80: fry | H80: 36 | J80: 0.48 | K80: N | M80: N | Q80: N | T80: N | U80: N | V80: N | W80: N | X80: N | Y80: N | Z80: N | AA80: N | AB80: Y | AD80: split dorsal fin | AE80: =IF(J80="", "", 100000*(J80/(H80^3))) -> 1.0288066
A81: 2023 | B81: 6' RST | C81: 30Mar23-RST-N | D81: =DATEVALUE(LEFT(C81, SEARCH("-", C81) - 1)) -> 45015 | E81: =D81 - DATE(YEAR(D81), 1, 0) -> 89 | F81: coho | G81: fry | H81: 37 | J81: 0.49 | K81: N | M81: N | Q81: N | T81: N | U81: N | V81: N | W81: N | X81: N | Y81: N | Z81: N | AA81: N | AB81: N | AE81: =IF(J81="", "", 100000*(J81/(H81^3))) -> 0.9673662
A82: 2023 | B82: 6' RST | C82: 30Mar23-RST-N | D82: =DATEVALUE(LEFT(C82, SEARCH("-", C82) - 1)) -> 45015 | E82: =D82 - DATE(YEAR(D82), 1, 0) -> 89 | F82: coho | G82: fry | H82: 34 | J82: 0.37 | K82: N | M82: N | Q82: N | T82: N | U82: N | V82: N | W82: N | X82: N | Y82: N | Z82: N | AA82: N | AB82: N | AE82: =IF(J82="", "", 100000*(J82/(H82^3))) -> 0.94138001
A83: 2023 | B83: 6' RST | C83: 30Mar23-RST-N | D83: =DATEVALUE(LEFT(C83, SEARCH("-", C83) - 1)) -> 45015 | E83: =D83 - DATE(YEAR(D83), 1, 0) -> 89 | F83: coho | G83: fry | H83: 37 | J83: 0.45 | K83: N | M83: N | Q83: N | T83: N | U83: N | V83: N | W83: N | X83: N | Y83: N | Z83: N | AA83: N | AB83: N | AE83: =IF(J83="", "", 100000*(J83/(H83^3))) -> 0.88839753
A84: 2023 | B84: 6' RST | C84: 30Mar23-RST-N | D84: =DATEVALUE(LEFT(C84, SEARCH("-", C84) - 1)) -> 45015 | E84: =D84 - DATE(YEAR(D84), 1, 0) -> 89 | F84: coho | G84: fry | H84: 38 | J84: 0.47 | K84: N | M84: N | Q84: N | T84: N | U84: N | V84: N | W84: N | X84: N | Y84: N | Z84: N | AA84: N | AB84: N | AE84: =IF(J84="", "", 100000*(J84/(H84^3))) -> 0.85653885
A85: 2023 | B85: 6' RST | C85: 30Mar23-RST-N | D85: =DATEVALUE(LEFT(C85, SEARCH("-", C85) - 1)) -> 45015 | E85: =D85 - DATE(YEAR(D85), 1, 0) -> 89 | F85: coho | G85: fry | H85: 36 | J85: 0.43 | K85: N | M85: N | Q85: N | T85: N | U85: N | V85: N | W85: N | X85: N | Y85: N | Z85: N | AA85: N | AB85: N | AE85: =IF(J85="", "", 100000*(J85/(H85^3))) -> 0.92163923
A86: 2023 | B86: 6' RST | C86: 30Mar23-RST-N | D86: =DATEVALUE(LEFT(C86, SEARCH("-", C86) - 1)) -> 45015 | E86: =D86 - DATE(YEAR(D86), 1, 0) -> 89 | F86: coho | G86: fry | H86: 36 | J86: 0.43 | K86: N | M86: N | Q86: N | T86: N | U86: N | V86: N | W86: N | X86: N | Y86: N | Z86: N | AA86: N | AB86: N | AE86: =IF(J86="", "", 100000*(J86/(H86^3))) -> 0.92163923
A87: 2023 | B87: 6' RST | C87: 30Mar23-RST-N | D87: =DATEVALUE(LEFT(C87, SEARCH("-", C87) - 1)) -> 45015 | E87: =D87 - DATE(YEAR(D87), 1, 0) -> 89 | F87: coho | G87: fry | H87: 36 | J87: 0.44 | K87: N | M87: N | Q87: N | T87: N | U87: N | V87: N | W87: N | X87: N | Y87: N | Z87: N | AA87: N | AB87: N | AE87: =IF(J87="", "", 100000*(J87/(H87^3))) -> 0.9430727
A88: 2023 | B88: 6' RST | C88: 30Mar23-RST-N | D88: =DATEVALUE(LEFT(C88, SEARCH("-", C88) - 1)) -> 45015 | E88: =D88 - DATE(YEAR(D88), 1, 0) -> 89 | F88: coho | G88: fry | H88: 38 | J88: 0.47 | K88: N | M88: N | Q88: N | T88: N | U88: N | V88: N | W88: N | X88: N | Y88: N | Z88: N | AA88: N | AB88: N | AE88: =IF(J88="", "", 100000*(J88/(H88^3))) -> 0.85653885
...

Sheet mark-release
A1: catch_date | B1: release_date | C1: release_time | D1: release_location_lat | E1: release_location_long | F1: marking_time_start | G1: marking_time_end | H1: time_marked | I1: species | J1: life_stage | K1: marking_morts | L1: total_released | M1: comments
A2: 45364 | B2: 45364 | C2: 18:23 | D2: 48.577768 | E2: -124.29936 | H2: ~1hr | I2: chinook | J2: fry | K2: 0 | L2: 2 | M2: lat/longs from google earth
A3: 45364 | B3: 45364 | C3: 18:23 | D3: 48.577768 | E3: -124.29936 | H3: ~1hr | I3: chum | J3: fry | K3: 0 | L3: 2 | M3: lat/longs from google earth
A4: 45370 | B4: 45370 | C4: 12:40 | D4: 48.578102 | E4: -124.30438 | H4: ~1hr | I4: chinook | J4: fry | K4: 0 | L4: 24
A5: 45370 | B5: 45370 | C5: 12:40 | D5: 48.578102 | E5: -124.30438 | H5: ~1hr | I5: coho | J5: fry | K5: 0 | L5: 146
A6: 45370 | B6: 45370 | C6: 12:40 | D6: 48.578102 | E6: -124.30438 | H6: ~1hr | I6: chum | J6: fry | K6: 0 | L6: 24 or 18?
A7: 45377 | B7: 45377 | C7: 09:42 | D7: 48.577768 | E7: -124.29936 | H7: ~1hr | I7: chinook | J7: fry | K7: 0 | L7: 3 | M7: lat/longs from google earth
A8: 45377 | B8: 45377 | C8: 09:42 | D8: 48.577768 | E8: -124.29936 | H8: ~1hr | I8: coho | J8: fry | K8: 0 | L8: 3 | M8: lat/longs from google earth
A9: 45377 | B9: 45377 | C9: 09:42 | D9: 48.577768 | E9: -124.29936 | H9: ~1hr | I9: coho | J9: smolt | K9: 0 | L9: 7 | M9: lat/longs from google earth
A10: 45378 | B10: 45378 | C10: 17:40 | D10: 48.578072 | E10: -124.30419 | H10: ~1hr | I10: coho | J10: smolt | K10: 0 | L10: 1
A11: 45378 | B11: 45378 | C11: 17:40 | D11: 48.578072 | E11: -124.30419 | H11: ~1hr | I11: chinook | J11: fry | K11: 0 | L11: 32
A12: 45378 | B12: 45378 | C12: 17:40 | D12: 48.578072 | E12: -124.30419 | H12: ~1hr | I12: coho | J12: fry | K12: 0 | L12: 318
A13: 45378 | B13: 45378 | C13: 17:40 | D13: 48.578072 | E13: -124.30419 | H13: ~1hr | I13: chum | J13: fry | K13: 0 | L13: 3
A14: 45385 | B14: 45385 | C14: 16:41 | D14: 48.577807 | E14: -124.29991 | H14: ~1hr | I14: chinook | J14: fry | K14: 0 | L14: 35
A15: 45385 | B15: 45385 | C15: 16:41 | D15: 48.577807 | E15: -124.29991 | H15: ~1hr | I15: coho | J15: fry | K15: 0 | L15: 487
A16: 45385 | B16: 45385 | C16: 16:41 | D16: 48.577807 | E16: -124.29991 | H16: ~1hr | I16: chum | J16: fry | K16: 0 | L16: 2
A17: 45385 | B17: 45385 | C17: 16:41 | D17: 48.577807 | E17: -124.29991 | H17: ~1hr | I17: coho | J17: smolt | K17: 2 | L17: 5 | M17: assume 2 morts - mis-match between #s caught and released dyed
A18: 45391 | B18: 45391 | C18: 17:30 | D18: 48.578075 | E18: -124.30413 | H18: ~1hr | I18: coho | J18: smolt | K18: 0 | L18: 1
A19: 45391 | B19: 45391 | C19: 17:30 | D19: 48.578075 | E19: -124.30413 | H19: ~1hr | I19: chinook | J19: fry | K19: 0 | L19: 16
A20: 45391 | B20: 45391 | C20: 17:30 | D20: 48.578075 | E20: -124.30413 | H20: ~1hr | I20: coho | J20: fry | K20: 0 | L20: 33
A21: 45391 | B21: 45391 | C21: 17:30 | D21: 48.578075 | E21: -124.30413 | H21: ~1hr | I21: chum | J21: fry | K21: 0 | L21: 2
A22: 45392 | B22: 45392 | C22: 17:34 | D22: 48.577794 | E22: -124.3 | H22: ~1hr | I22: coho | J22: fry | K22: 0 | L22: 70 | M22: 27 morts 15 were stuck in the cone and the rest were in the trap in the debris. 1 coho was not swimming to good in the Bismarck dying bucket so I put it in the fresh water bucket and didnâ€™t make it it was too weak by then.
A23: 45392 | B23: 45392 | C23: 17:34 | D23: 48.577794 | E23: -124.3 | H23: ~1hr | I23: coho | J23: smolt | K23: 1 | L23: 9 | M23: 27 morts 15 were stuck in the cone and the rest were in the trap in the debris. 1 coho was not swimming to good in the Bismarck dying bucket so I put it in the fresh water bucket and didnâ€™t make it it was too weak by then.
A24: 45398 | B24: 45398 | C24: 13:15 | D24: 48.578123 | E24: -124.3042 | H24: ~1hr | I24: coho | J24: smolt | K24: 0 | L24: 2
A25: 45398 | B25: 45398 | C25: 13:15 | D25: 48.578123 | E25: -124.3042 | H25: ~1hr | I25: coho | J25: fry | K25: 0 | L25: 13
A26: 45399 | B26: 45399 | C26: 13:35 | D26: 48.577831 | E26: -124.29988 | H26: ~1hr | I26: coho | J26: smolt | K26: 0 | L26: 4
A27: 45399 | B27: 45399 | C27: 13:35 | D27: 48.577831 | E27: -124.29988 | H27: ~1hr | I27: chinook | J27: fry | K27: 0 | L27: 3
A28: 45399 | B28: 45399 | C28: 13:35 | D28: 48.577831 | E28: -124.29988 | H28: ~1hr | I28: coho | J28: fry | K28: 0 | L28: 44
A29: 45399 | B29: 45399 | C29: 13:35 | D29: 48.577831 | E29: -124.29988 | H29: ~1hr | I29: chum | J29: fry | K29: 0 | L29: 2
A30: 45405 | B30: 45405 | C30: 15:15 | D30: 48.578104 | E30: -124.30416 | H30: ~1hr | I30: chinook | J30: fry | K30: 0 | L30: 1
A31: 45405 | B31: 45405 | C31: 15:15 | D31: 48.578104 | E31: -124.30416 | H31: ~1hr | I31: coho | J31: fry | K31: 0 | L31: 31
A32: 45405 | B32: 45405 | C32: 15:15 | D32: 48.578104 | E32: -124.30416 | H32: ~1hr | I32: coho | J32: smolt | K32: 0 | L32: 3
A33: 45405 | B33: 45405 | C33: 15:15 | D33: 48.578104 | E33: -124.30416 | H33: ~1hr | I33: chum | J33: fry | K33: 0 | L33: 3
A34: 45407 | B34: 45407 | C34: 15:00 | D34: 48.576919 | E34: -124.30878 | K34: 0 | L34: 0 | M34: Released down river from RST, by a tree and roots so the fry have a place to hide; We will be releasing marked fish down river of the RST today. Keeping note here for records.
A35: 45408 | B35: 45408 | C35: 12:34 | D35: 48.576828 | E35: -124.30873 | K35: 0 | L35: 0 | M35: Releasing down river of RST; 4 morts during marking. Not relevant for RST mark-recap
A36: 45412 | B36: 45412 | C36: 15:51 | D36: 48.577767 | E36: -124.29996 | H36: ~1hr | I36: coho | J36: fry | K36: 4 | L36: 237
A37: 45412 | B37: 45412 | C37: 15:51 | D37: 48.577767 | E37: -124.29996 | H37: ~1hr | I37: rainbow | J37: fry / parr | K37: 0 | L37: 2
A38: 45412 | B38: 45412 | C38: 15:51 | D38: 48.577767 | E38: -124.29996 | H38: ~1hr | I38: coho | J38: smolt | K38: 0 | L38: 5 | M38: 4coho morts from Bismarck
A39: 45413 | B39: 45413 | C39: 12:24 | D39: 48.578066 | E39: -124.30417 | H39: ~1hr | I39: chinook | J39: fry | K39: 0 | L39: 2
A40: 45413 | B40: 45413 | C40: 12:24 | D40: 48.578066 | E40: -124.30417 | H40: ~1hr | I40: coho | J40: fry | K40: 0 | L40: 209
...

Sheet Sheet4
A1: gear | B1: (Multiple Items)
A2: year | B2: 2024
T3: march 19 2024
A4: Count of length | B4: Column Labels | U4: 1 coho mort biosampled (29 released live)
A5: Row Labels | B5: fry | C5: smolt | D5: Grand Total
A6: 45364 | B6: 4 | D6: 4
A7: chinook | B7: 2 | D7: 2
A8: chum | B8: 2 | D8: 2
A9: 45365 | B9: 3 | D9: 3
A10: chinook | B10: 2 | D10: 2
A11: coho | B11: 1 | D11: 1
A12: 45366 | B12: 1 | D12: 1
A13: chinook | B13: 1 | D13: 1
A14: 45370 | B14: 72 | D14: 72
A15: chinook | B15: 24 | D15: 24
A16: chum | B16: 18 | D16: 18
A17: coho | B17: 30 | D17: 30
A18: 45371 | B18: 32 | D18: 32
A19: chinook | B19: 14 | D19: 14
A20: chum | B20: 4 | D20: 4
A21: coho | B21: 14 | D21: 14
A22: 45372 | B22: 117 | C22: 2 | D22: 119
A23: chinook | B23: 40 | D23: 40
A24: chum | B24: 14 | D24: 14
A25: coho | B25: 63 | C25: 2 | D25: 65
A26: 45377 | B26: 6 | C26: 7 | D26: 13
A27: chinook | B27: 3 | D27: 3
A28: coho | B28: 3 | C28: 7 | D28: 10
A29: 45378 | B29: 63 | C29: 1 | D29: 64
A30: chinook | B30: 32 | D30: 32
A31: chum | B31: 3 | D31: 3
A32: coho | B32: 27 | C32: 1 | D32: 28
A33: Other | B33: 1 | D33: 1
A34: 45379 | B34: 46 | C34: 5 | D34: 51
A35: chinook | B35: 15 | D35: 15
A36: chum | B36: 1 | D36: 1
A37: coho | B37: 30 | C37: 5 | D37: 35
A38: 45385 | B38: 66 | C38: 7 | D38: 73
A39: chinook | B39: 32 | D39: 32
A40: chum | B40: 2 | D40: 2
...

Sheet lethal sample pivot
B2: frozen_lethal | C2: (Multiple Items)
B4: Count of frozen_lethal | C4: Column Labels
B5: Row Labels | C5: 6' RST | D5: Beach seine | E5: Dip net | F5: IPT | G5: Mini purse seine | H5: Grand Total
B6: 2023 | C6: 7 | D6: 25 | E6: 120 | G6: 5 | H6: 157
B7: 2024 | C7: 49 | F7: 3 | G7: 77 | H7: 129
B8: 2025 | C8: 55 | D8: 15 | G8: 24 | H8: 94
B9: Grand Total | C9: 111 | D9: 40 | E9: 120 | F9: 3 | G9: 106 | H9: 380
B19: BEACH SEINE FILE:
B21: Lethal Sample (Y/N) | C21: Y
B23: Row Labels | C23: Count of Lethal Sample (Y/N)
B24: CN | C24: 103
B25: 24-05-27 | C25: 1
B26: 24-06-13 | C26: 19
B27: 24-06-14 | C27: 2
B28: 24-06-17 | C28: 13
B29: 24-06-24 | C29: 1
B30: 24-06-25 | C30: 20
B31: 24-06-26 | C31: 2
B32: 24-06-27 | C32: 1
B33: 24-07-02 | C33: 12
B34: 24-07-11 | C34: 15
B35: 24-07-12 | C35: 3
... B40: Grand Total | C40: 103

Sheet Samples missing data
A1: Samples shipped that aren't in the database
A3: Number | B3: Comment
A4: SJ24m-PRS463 | B4: Present on COC but not in the data
A5: SJ24m-PRS470 | B5: Present on the COC three times. One of them must be 471
A6: SJ25-410 | B6: 410 was shipped to Biologica but the data has it as 409. Field entry error?
A7: SJ25-421 | B7: 420 was shipped to Biologica but the data has it as 421. Field entry error?
A8: SJ25-431 | B8: 431 was shipped to Biologica but the data has it as 430. Field entry error?
A9: SJF25-3-18-1 | B9: Was shipped to Zootaxy but not in our database
A10: SJF25-3-18-2 | B10: Was shipped to Zootaxy but not in our database
A11: SJF25-3-18-3 | B11: Was shipped to Zootaxy but not in our database
A12: SJ25-016 | B12: Was shipped to Zootaxy but not in our database
A13: SJ25-017 | B13: Was shipped to Zootaxy but not in our database
A14: SJ25-018 | B14: Was shipped to Zootaxy but not in our database
... A31: SJ25-035 | B31: Was shipped to Zootaxy but not in our database
